<?xml version="1.0" ?>
<robot name="lezl">
  <joint name="/imu_joint" type="fixed">
    <parent link="base_link"/>
    <child link="/imu_link"/>
    <origin rpy="0  0  0" xyz="0  0  0"/>
    <axis xyz="1  0  0"/>
    <limit effort="0.0" lower="0.0" upper="0.0" velocity="0.0"/>
  </joint>
  <joint name="rotor_0_joint" type="revolute">
    <parent link="base_link"/>
    <child link="rotor_0"/>
    <origin rpy="0  0  0" xyz="0.162 -0.162  0.007"/>
    <axis xyz="0  0  1"/>
    <limit effort="0.0" lower="-1e+16" upper="1e+16" velocity="0.0"/>
  </joint>
  <joint name="rotor_1_joint" type="revolute">
    <parent link="base_link"/>
    <child link="rotor_1"/>
    <origin rpy="0  0  0" xyz="-0.162  0.162  0.007"/>
    <axis xyz="0  0  1"/>
    <limit effort="0.0" lower="-1e+16" upper="1e+16" velocity="0.0"/>
  </joint>
  <joint name="rotor_2_joint" type="revolute">
    <parent link="base_link"/>
    <child link="rotor_2"/>
    <origin rpy="0  0  0" xyz="0.162  0.162  0.007"/>
    <axis xyz="0  0  1"/>
    <limit effort="0.0" lower="-1e+16" upper="1e+16" velocity="0.0"/>
  </joint>
  <joint name="rotor_3_joint" type="revolute">
    <parent link="base_link"/>
    <child link="rotor_3"/>
    <origin rpy="0  0  0" xyz="-0.162 -0.162  0.007"/>
    <axis xyz="0  0  1"/>
    <limit effort="0.0" lower="-1e+16" upper="1e+16" velocity="0.0"/>
  </joint>
  <link name="base_link">
    <inertial>
      <mass value="1.5"/>
      <origin rpy="0  0  0" xyz="0  0  0"/>
      <inertia ixx="0.0347563" ixy="0" ixz="0" iyy="0.0458929" iyz="0" izz="0.0977"/>
    </inertial>
    <collision name="base_link_inertia_collision">
      <origin rpy="0  0  0" xyz="0  0  0"/>
      <geometry>
        <box size="0.47 0.47 0.37"/>
      </geometry>
    </collision>
    <visual name="base_link_inertia_visual">
      <origin rpy="1.57  0    0" xyz="0.01799 -0.0265   0"/>
      <geometry>
        <mesh filename="package://irols/gazebo/models/lezl/meshes/f450_frame.stl" scale="0.001 0.001 0.001"/>
      </geometry>
    </visual>
  </link>
  <link name="/imu_link">
    <inertial>
      <mass value="0.015"/>
      <origin rpy="0  0  0" xyz="0  0  0"/>
      <inertia ixx="1e-05" ixy="0" ixz="0" iyy="1e-05" iyz="0" izz="1e-05"/>
    </inertial>
  </link>
  <link name="rotor_0">
    <inertial>
      <mass value="0.005"/>
      <origin rpy="0  0  0" xyz="0  0  0"/>
      <inertia ixx="9.75e-07" ixy="0" ixz="0" iyy="0.000273104" iyz="0" izz="0.000274004"/>
    </inertial>
    <collision name="rotor_0_collision">
      <origin rpy="0  0  0" xyz="0  0  0"/>
      <geometry>
        <cylinder length="0.005" radius="0.128"/>
      </geometry>
    </collision>
    <visual name="rotor_0_visual">
      <origin rpy="1.57  0    0" xyz="0  0  0"/>
      <geometry>
        <mesh filename="package://irols/gazebo/models/lezl/meshes/f450_prop_ccw.stl" scale="0.001 0.001 0.001"/>
      </geometry>
    </visual>
  </link>
  <link name="rotor_1">
    <inertial>
      <mass value="0.005"/>
      <origin rpy="0  0  0" xyz="0  0  0"/>
      <inertia ixx="9.75e-07" ixy="0" ixz="0" iyy="0.000273104" iyz="0" izz="0.000274004"/>
    </inertial>
    <collision name="rotor_1_collision">
      <origin rpy="0  0  0" xyz="0  0  0"/>
      <geometry>
        <cylinder length="0.005" radius="0.128"/>
      </geometry>
    </collision>
    <visual name="rotor_1_visual">
      <origin rpy="1.57  0    0" xyz="0  0  0"/>
      <geometry>
        <mesh filename="package://irols/gazebo/models/lezl/meshes/f450_prop_ccw.stl" scale="0.001 0.001 0.001"/>
      </geometry>
    </visual>
  </link>
  <link name="rotor_2">
    <inertial>
      <mass value="0.005"/>
      <origin rpy="0  0  0" xyz="0  0  0"/>
      <inertia ixx="9.75e-07" ixy="0" ixz="0" iyy="0.000273104" iyz="0" izz="0.000274004"/>
    </inertial>
    <collision name="rotor_2_collision">
      <origin rpy="0  0  0" xyz="0  0  0"/>
      <geometry>
        <cylinder length="0.005" radius="0.128"/>
      </geometry>
    </collision>
    <visual name="rotor_2_visual">
      <origin rpy="1.57  0    0" xyz="0  0  0"/>
      <geometry>
        <mesh filename="package://irols/gazebo/models/lezl/meshes/f450_prop_cw.stl" scale="0.001 0.001 0.001"/>
      </geometry>
    </visual>
  </link>
  <link name="rotor_3">
    <inertial>
      <mass value="0.005"/>
      <origin rpy="0  0  0" xyz="0  0  0"/>
      <inertia ixx="9.75e-07" ixy="0" ixz="0" iyy="0.000273104" iyz="0" izz="0.000274004"/>
    </inertial>
    <collision name="rotor_3_collision">
      <origin rpy="0  0  0" xyz="0  0  0"/>
      <geometry>
        <cylinder length="0.005" radius="0.128"/>
      </geometry>
    </collision>
    <visual name="rotor_3_visual">
      <origin rpy="1.57  0    0" xyz="0  0  0"/>
      <geometry>
        <mesh filename="package://irols/gazebo/models/lezl/meshes/f450_prop_cw.stl" scale="0.001 0.001 0.001"/>
      </geometry>
    </visual>
  </link>
</robot>
